Unhandled exception in thread started by <function check_errors.<locals>.wrapper at 0x0344DD68>
Traceback (most recent call last):
  File "C:\djangoecommerce\venv\lib\site-packages\django\utils\autoreload.py", line 225, in wrapper
    fn(*args, **kwargs)
  File "C:\djangoecommerce\venv\lib\site-packages\django\core\management\commands\runserver.py", line 120, in inner_run
    self.check(display_num_errors=True)
  File "C:\djangoecommerce\venv\lib\site-packages\django\core\management\base.py", line 364, in check
    include_deployment_checks=include_deployment_checks,
  File "C:\djangoecommerce\venv\lib\site-packages\django\core\management\base.py", line 351, in _run_checks
    return checks.run_checks(**kwargs)
  File "C:\djangoecommerce\venv\lib\site-packages\django\core\checks\registry.py", line 73, in run_checks
    new_errors = check(app_configs=app_configs)
  File "C:\djangoecommerce\venv\lib\site-packages\django\core\checks\urls.py", line 13, in check_url_config
    return check_resolver(resolver)
  File "C:\djangoecommerce\venv\lib\site-packages\django\core\checks\urls.py", line 23, in check_resolver
    return check_method()
  File "C:\djangoecommerce\venv\lib\site-packages\django\urls\resolvers.py", line 399, in check
    for pattern in self.url_patterns:
  File "C:\djangoecommerce\venv\lib\site-packages\django\utils\functional.py", line 36, in __get__
    res = instance.__dict__[self.name] = self.func(instance)
  File "C:\djangoecommerce\venv\lib\site-packages\django\urls\resolvers.py", line 540, in url_patterns
    patterns = getattr(self.urlconf_module, "urlpatterns", self.urlconf_module)
  File "C:\djangoecommerce\venv\lib\site-packages\django\utils\functional.py", line 36, in __get__
    res = instance.__dict__[self.name] = self.func(instance)
  File "C:\djangoecommerce\venv\lib\site-packages\django\urls\resolvers.py", line 533, in urlconf_module
    return import_module(self.urlconf_name)
  File "C:\Users\gnovaes\AppData\Local\Programs\Python\Python36-32\lib\importlib\__init__.py", line 126, in import_module
    return _bootstrap._gcd_import(name[level:], package, level)
  File "<frozen importlib._bootstrap>", line 978, in _gcd_import
  File "<frozen importlib._bootstrap>", line 961, in _find_and_load
  File "<frozen importlib._bootstrap>", line 950, in _find_and_load_unlocked
  File "<frozen importlib._bootstrap>", line 655, in _load_unlocked
  File "<frozen importlib._bootstrap_external>", line 678, in exec_module
  File "<frozen importlib._bootstrap>", line 205, in _call_with_frames_removed
  File "C:\djangoecommerce\djangoecommerce\urls.py", line 27, in <module>
  File "C:\djangoecommerce\venv\lib\site-packages\django\urls\conf.py", line 39, in include
    'Specifying a namespace in include() without providing an app_name '
django.core.exceptions.ImproperlyConfigured: Specifying a namespace in include() without providing an app_name is not supported. Set the app_name attribute in the included module, or pass a 2-tuple containing the list of patterns and app_name instead.

During handling of the above exception, another exception occurred:

Traceback (most recent call last):
  File "C:\djangoecommerce\venv\lib\site-packages\django\utils\autoreload.py", line 233, in wrapper
    filename = traceback.extract_tb(tb)[-1][0]
  File "C:\Users\gnovaes\AppData\Local\Programs\Python\Python36-32\lib\traceback.py", line 68, in extract_tb
    return StackSummary.extract(walk_tb(tb), limit=limit)
  File "C:\Users\gnovaes\AppData\Local\Programs\Python\Python36-32\lib\traceback.py", line 358, in extract
    f.line
  File "C:\Users\gnovaes\AppData\Local\Programs\Python\Python36-32\lib\traceback.py", line 282, in line
    self._line = linecache.getline(self.filename, self.lineno).strip()
  File "C:\Users\gnovaes\AppData\Local\Programs\Python\Python36-32\lib\linecache.py", line 16, in getline
    lines = getlines(filename, module_globals)
  File "C:\Users\gnovaes\AppData\Local\Programs\Python\Python36-32\lib\linecache.py", line 47, in getlines
    return updatecache(filename, module_globals)
  File "C:\Users\gnovaes\AppData\Local\Programs\Python\Python36-32\lib\linecache.py", line 137, in updatecache
    lines = fp.readlines()
  File "C:\Users\gnovaes\AppData\Local\Programs\Python\Python36-32\lib\codecs.py", line 321, in decode
    (result, consumed) = self._buffer_decode(data, self.errors, final)
UnicodeDecodeError: 'utf-8' codec can't decode byte 0xe3 in position 670: invalid continuation byte
^C